Workbook

Sheet Leeme
A1: Balance de Junked Metal. Esta planilla se genera desde src/balance.json (npm run balance:xlsx) y vuelve al juego con npm run balance:import.
A2: Hojas de datos (se importan): enemigos, armas, armas_extra, pasivas, ritmo, ataques, autos, pilotos, precios, plagas, duelo, duelo_bloques, duelo_chasis, duelo_ruedas, duelo_armas, duelo_rival. Fila 1 = columnas, fila 2 = qué significa cada una.
A3: Se editan SOLO los números. No cambiar los id, no agregar ni borrar filas ni columnas (el importador lo rechaza). Las columnas nombre y tipo son referencia.
A4: Hojas calculadas (no se importan): Golpes para matar, Tiempo jefe, Partidas para comprar. Se actualizan solas. Las celdas amarillas son supuestos editables solo de la hoja calculada.
A5: Para volver al juego: Archivo > Descargar > Valores separados por tabulaciones (.tsv) de cada hoja de datos, juntar en un .txt con una línea '### nombre_hoja' antes de cada una y correr npm run balance:import -- archivo.txt.
A6: Usar punto decimal (configuración regional de EE. UU.) o coma sin separador de miles. El importador avisa de las diferencias antes de escribir el JSON.

Sheet enemigos
A1: id | B1: nombre | C1: tipo | D1: vida | E1: velocidad | F1: dano | G1: peso | H1: xp | I1: aparece_min | J1: peso_base | K1: peso_por_min
A2: Identificador del bicho (no cambiar) | B2: Nombre (referencia: el juego usa el del código) | C2: bicho, minijefe o jefe_final (referencia: define cómo calcula la hoja Golpes para matar) | D2: Vida base. Bichos normales: × ritmo.dureza_vida y × el escalado por tiempo; jefes: se usa tal cual | E2: Velocidad máxima (m/s) | F2: Daño base de contacto (golpe real = dano × ritmo.contacto_dano; × dureza en bichos normales) | G2: Masa física: cuánto cuesta empujarlo | H2: Tuercas de XP que suelta (× dureza_xp en bichos normales) | I2: Minuto desde el que entra en la mezcla común (las plagas pueden adelantarlo) | J2: Peso de aparición en la mezcla al llegar a su minuto | K2: Peso extra por cada minuto de partida
A3: hormiga | B3: Hormiga | C3: bicho | D3: 11 | E3: 8 | F3: 6 | G3: 0.4 | H3: 1 | I3: 0 | J3: 10 | K3: 0
A4: escupidora | B4: Hormiga escupidora | C4: bicho | D4: 22 | E4: 7 | F4: 8 | G4: 0.7 | H4: 3 | I4: 1.5 | J4: 1 | K4: 0.6
A5: friccion | B5: Autito a fricción | C5: bicho | D5: 18 | E5: 12.5 | F5: 7 | G5: 0.7 | H5: 2 | I5: 0.5 | J5: 4 | K5: 1
A6: robot | B6: Robot a cuerda | C6: bicho | D6: 40 | E6: 18 | F6: 10 | G6: 1.3 | H6: 3 | I6: 1.5 | J6: 2 | K6: 0.6
A7: polilla | B7: Polilla | C7: bicho | D7: 12 | E7: 11 | F7: 5 | G7: 0.3 | H7: 2 | I7: 2.5 | J7: 1 | K7: 0.4
A8: escarabajo | B8: Escarabajo | C8: bicho | D8: 90 | E8: 4.5 | F8: 12 | G8: 3 | H8: 6 | I8: 3.5 | J8: 1 | K8: 0.5
A9: rey | B9: ESCARABAJO REY | C9: minijefe | D9: 1800 | E9: 6 | F9: 30 | G9: 40 | H9: 60 | I9: 0 | J9: 0 | K9: 0
A10: cortadora | B10: CORTADORA DE CÉSPED | C10: minijefe | D10: 3500 | E10: 15 | F10: 45 | G10: 80 | H10: 120 | I10: 0 | J10: 0 | K10: 0
A11: tarantula | B11: TARÁNTULA | C11: minijefe | D11: 2600 | E11: 7 | F11: 35 | G11: 50 | H11: 100 | I11: 0 | J11: 0 | K11: 0
A12: gato | B12: EULALIO EL MICHU | C12: minijefe | D12: 2900 | E12: 11 | F12: 32 | G12: 60 | H12: 110 | I12: 0 | J12: 0 | K12: 0
A13: proyector | B13: EL PROYECTOR DEL DIRECTOR | C13: minijefe | D13: 3200 | E13: 6 | F13: 28 | G13: 45 | H13: 95 | I13: 0 | J13: 0 | K13: 0
A14: grua | B14: LA GRÚA DE FERIA | C14: minijefe | D14: 3300 | E14: 6.5 | F14: 30 | G14: 55 | H14: 100 | I14: 0 | J14: 0 | K14: 0
... A36: gusano | B36: GUSANO LUNAR | C36: jefe_final | D36: 6000 | E36: 14 | F36: 40 | G36: 100 | H36: 0 | I36: 0 | J36: 0 | K36: 0

Sheet armas
A1: id | B1: nombre | C1: unidad_dano | D1: dano_base | E1: dano_nivel | F1: dano_evo_mult | G1: dano_evo_fijo | H1: recarga_base | I1: recarga_min | J1: recarga_nivel | K1: recarga_div | L1: recarga_evo | M1: recarga_evo_div | N1: alcance | O1: alcance_evo | P1: area_base | Q1: area_nivel | R1: area_evo | S1: n_base | T1: n_cada | U1: n_desde | V1: n_evo | W1: duracion_base | X1: duracion_nivel | Y1: duracion_evo | Z1: velocidad
A2: Identificador del arma (no cambiar) | B2: Nombre (referencia) | C2: Qué significa un golpe de esa arma (referencia, para leer la hoja Golpes para matar) | D2: Daño = dano_base + dano_nivel × nivel (antes del daño del equipo) | E2: Daño extra por nivel (Lápiz-lanza: +fracción de embestida por nivel) | F2: Evolución: multiplicador del daño normal | G2: Evolución: daño fijo (0 = no aplica; manda sobre el multiplicador) | H2: Segundos entre disparos al nivel 0 | I2: Piso de la recarga (segundos) | J2: Segundos menos de recarga por nivel: max(piso, base − nivel × N) | K2: Solo Gomitas y Helado: recarga = base ÷ (1 + div × (nivel − 1)) | L2: Evolución: recarga fija en segundos (0 = no aplica) | M2: Evolución: divisor de la recarga (1 = sin cambio) | N2: Distancia (m) a la que busca objetivo | O2: Ídem evolucionada (0 = no aplica) | P2: Radio, largo o tamaño del efecto (m) al nivel 0 | Q2: Metros extra por nivel | R2: Ídem evolucionada (0 = no aplica; Lápiz-lanza: radio de la onda del Ariete) | S2: Proyectiles: base | T2: Proyectiles: uno más cada tantos niveles | U2: Proyectiles: cantidad = base + piso((nivel − desde) ÷ cada) | V2: Evolución: cantidad fija (0 = no aplica) | W2: Segundos de vida del proyectil, zona o chorro | X2: Segundos extra por nivel | Y2: Ídem evolucionada (0 = no aplica) | Z2: Velocidad del proyectil (m/s)
A3: gomitas | B3: Lanza-gomitas | C3: por impacto | D3: 5 | E3: 3 | F3: 1.4 | G3: 0 | H3: 1.1 | I3: 0 | J3: 0 | K3: 0.12 | L3: 0 | M3: 1.5 | N3: 22 | O3: 0 | P3: 0 | Q3: 0 | R3: 0 | S3: 1 | T3: 2 | U3: 1 | V3: 5 | W3: 1.2 | X3: 0 | Y3: 0 | Z3: 30
A4: clips | B4: Clips orbitales | C4: por golpe (cada 0,35 s) | D4: 8 | E4: 4 | F4: 1 | G4: 30 | H4: 0 | I4: 0 | J4: 0 | K4: 0 | L4: 0 | M4: 1 | N4: 0 | O4: 0 | P4: 2.6 | Q4: 0 | R4: 4.5 | S4: 1 | T4: 1 | U4: 0 | V4: 8 | W4: 0 | X4: 0 | Y4: 0 | Z4: 0
A5: chispero | B5: Chispero | C5: por segundo | D5: 10 | E5: 6 | F5: 1 | G5: 50 | H5: 0 | I5: 0 | J5: 0 | K5: 0 | L5: 0 | M5: 1 | N5: 0 | O5: 0 | P5: 0.8 | Q5: 0.08 | R5: 1.7 | S5: 0 | T5: 0 | U5: 0 | V5: 0 | W5: 1.2 | X5: 0.3 | Y5: 4 | Z5: 0
A6: petardos | B6: Petardos | C6: por explosión | D6: 30 | E6: 15 | F6: 1 | G6: 0 | H6: 3.2 | I6: 0.8 | J6: 0.3 | K6: 0 | L6: 0 | M6: 1 | N6: 18 | O6: 0 | P6: 3 | Q6: 0.3 | R6: 0 | S6: 1 | T6: 3 | U6: 0 | V6: 0 | W6: 0.6 | X6: 0 | Y6: 0 | Z6: 0
A7: tesla | B7: Antena Tesla | C7: por salto de la cadena | D7: 18 | E7: 8 | F7: 1.5 | G7: 0 | H7: 1.4 | I7: 0.5 | J7: 0.1 | K7: 0 | L7: 0.45 | M7: 1 | N7: 9 | O7: 0 | P7: 0 | Q7: 0 | R7: 0 | S7: 2 | T7: 1 | U7: 0 | V7: 10 | W7: 0 | X7: 0 | Y7: 0 | Z7: 0
A8: lanza | B8: Lápiz-lanza | C8: multiplicador de la embestida | D8: 0 | E8: 0.35 | F8: 1.5 | G8: 0 | H8: 0 | I8: 0 | J8: 0 | K8: 0 | L8: 0 | M8: 1 | N8: 0 | O8: 0 | P8: 0 | Q8: 0 | R8: 4 | S8: 0 | T8: 0 | U8: 0 | V8: 0 | W8: 0 | X8: 0 | Y8: 0 | Z8: 0
A9: agua | B9: Pistola de agua | C9: por pulso (cada 0,1 s) | D9: 3 | E9: 1.5 | F9: 1.6 | G9: 0 | H9: 1.9 | I9: 0.9 | J9: 0.15 | K9: 0 | L9: 0.4 | M9: 1 | N9: 0 | O9: 0 | P9: 8 | Q9: 0.6 | R9: 13 | S9: 0 | T9: 0 | U9: 0 | V9: 0 | W9: 0.5 | X9: 0.05 | Y9: 1.2 | Z9: 0
A10: yoyo | B10: Yo-yo | C10: por impacto | D10: 14 | E10: 6 | F10: 1 | G10: 40 | H10: 1.5 | I10: 0.6 | J10: 0.15 | K10: 0 | L10: 0 | M10: 1 | N10: 0 | O10: 0 | P10: 9 | Q10: 0.8 | R10: 0 | S10: 1 | T10: 2 | U10: 1 | V10: 0 | W10: 0 | X10: 0 | Y10: 0 | Z10: 26
A11: bengalas | B11: Bengalas | C11: por segundo en la zona | D11: 12 | E11: 6 | F11: 1 | G11: 45 | H11: 3.8 | I11: 1.8 | J11: 0.35 | K11: 0 | L11: 2.4 | M11: 1 | N11: 20 | O11: 24 | P11: 1.8 | Q11: 0.2 | R11: 3 | S11: 1 | T11: 2 | U11: 0 | V11: 6 | W11: 3 | X11: 0.4 | Y11: 5.5 | Z11: 0
A12: regla | B12: Bumerán de regla | C12: por impacto | D12: 12 | E12: 5 | F12: 1 | G12: 40 | H12: 1.4 | I12: 0.6 | J12: 0.15 | K12: 0 | L12: 0.5 | M12: 1 | N12: 0 | O12: 0 | P12: 10 | Q12: 1 | R12: 15 | S12: 1 | T12: 4 | U12: 0 | V12: 3 | W12: 1.4 | X12: 0 | Y12: 1.1 | Z12: 0
A13: helado | B13: Helado congelante | C13: por impacto | D13: 8 | E13: 3 | F13: 1.3 | G13: 0 | H13: 1.4 | I13: 0 | J13: 0 | K13: 0.1 | L13: 0 | M13: 1.3 | N13: 24 | O13: 0 | P13: 0 | Q13: 0 | R13: 0 | S13: 1 | T13: 4 | U13: 0 | V13: 3 | W13: 1.3 | X13: 0 | Y13: 0 | Z13: 26
A14: bocina | B14: Bocina | C14: por onda | D14: 9 | E14: 4 | F14: 1.5 | G14: 0 | H14: 2.6 | I14: 1.4 | J14: 0.2 | K14: 0 | L14: 2.2 | M14: 1 | N14: 0 | O14: 0 | P14: 8 | Q14: 0.8 | R14: 17 | S14: 0 | T14: 0 | U14: 0 | V14: 0 | W14: 0.45 | X14: 0 | Y14: 0 | Z14: 0
... A27: tambor | B27: Tambor de hojalata | C27: por onda | D27: 10 | E27: 4 | F27: 1.4 | G27: 0 | H27: 1.2 | I27: 0.7 | J27: 0.1 | K27: 0 | L27: 0.7 | M27: 1 | N27: 0 | O27: 0 | P27: 5 | Q27: 0.5 | R27: 9 | S27: 0 | T27: 0 | U27: 0 | V27: 0 | W27: 0.35 | X27: 0 | Y27: 2 | Z27: 0

Sheet pasivas
A1: id | B1: nombre | C1: base | D1: por_nivel | E1: base2 | F1: por_nivel2
A2: Identificador (no cambiar) | B2: Nombre (referencia) | C2: Valor base (solo Imán: radio de recolección en m) | D2: Efecto por nivel: Imán, Resorte y Lupa +fracción; Turbo +fracción de velocidad; Litio +vida máxima; Capacitor y LEGO: multiplicador compuesto (0,92 = −8% por nivel) | E2: Base del efecto secundario (Turbo: recarga del turbo por s; Litio: regeneración por s) | F2: Efecto secundario por nivel (Turbo: +fracción de recarga; Litio: regeneración por s; LEGO: +fracción de peso)
A3: iman | B3: Imán de heladera | C3: 6 | D3: 0.3 | E3: 0 | F3: 0
A4: resorte | B4: Resorte | C4: 0 | D4: 0.12 | E4: 0 | F4: 0
A5: turbo | B5: Motor turbo | C5: 0 | D5: 0.06 | E5: 14 | F5: 0.25
A6: litio | B6: Pila de litio | C6: 0 | D6: 20 | E6: 1 | F6: 0.5
A7: capacitor | B7: Capacitor | C7: 0 | D7: 0.92 | E7: 0 | F7: 0
A8: lego | B8: Paragolpes LEGO | C8: 0 | D8: 0.92 | E8: 0 | F8: 0.1
A9: lupa | B9: Lupa | C9: 0 | D9: 0.08 | E9: 0 | F9: 0

Sheet autos
A1: id | B1: nombre | C1: precio | D1: vida | E1: velocidad | F1: aceleracion | G1: giro | H1: agarre | I1: embestida | J1: masa
A2: Identificador (no cambiar) | B2: Nombre (referencia) | C2: Precio en tornillos (0 = de serie) | D2: Vida máxima | E2: Velocidad máxima (m/s) | F2: Aceleración (m/s²) | G2: Velocidad de giro | H2: Agarre lateral (más alto = menos derrape) | I2: Multiplicador del daño de embestida | J2: Masa (peso al chocar)
A3: buggy | B3: El Divorciado | C3: 0 | D3: 150 | E3: 15 | F3: 32 | G3: 3.2 | H3: 10 | I3: 3 | J3: 1
A4: monster | B4: El Loco Cuarentón | C4: 400 | D4: 220 | E4: 12.5 | F4: 26 | G4: 2.7 | H4: 12 | I4: 4.5 | J4: 1.8
A5: formula | B5: El Apurado | C5: 550 | D5: 110 | E5: 19 | F5: 40 | G5: 3.6 | H5: 14 | I5: 2.4 | J5: 0.8
A6: tanque | B6: El Suegro | C6: 800 | D6: 300 | E6: 10 | F6: 18 | G6: 2.3 | H6: 18 | I6: 5.5 | J6: 2.6
A7: carrera | B7: El Sin Seguro | C7: 650 | D7: 85 | E7: 21 | F7: 48 | G7: 4.2 | H7: 6 | I7: 1.8 | J7: 0.55
A8: axel | B8: El Sin Licencia | C8: 700 | D8: 120 | E8: 20 | F8: 38 | G8: 3.8 | H8: 8 | I8: 4 | J8: 1.2
A9: helado | B9: El Tío del Helado | C9: 650 | D9: 180 | E9: 13 | F9: 24 | G9: 2.8 | H9: 11 | I9: 3 | J9: 1.4
A10: combi | B10: El Tío Raro | C10: 900 | D10: 280 | E10: 11 | F10: 20 | G10: 2.4 | H10: 14 | I10: 4 | J10: 2.2
A11: hover | B11: El Capitán de Bañera | C11: 1200 | D11: 140 | E11: 17 | F11: 22 | G11: 2.2 | H11: 3 | I11: 2.5 | J11: 0.9
A12: topadora | B12: El Capataz | C12: 1500 | D12: 260 | E12: 9 | F12: 16 | G12: 2 | H12: 20 | I12: 6 | J12: 3
A13: triciclo | B13: El Repartidor | C13: 900 | D13: 95 | E13: 18 | F13: 34 | G13: 5 | H13: 16 | I13: 2 | J13: 0.7

Sheet pilotos
A1: id | B1: nombre | C1: precio | D1: dano_mult | E1: vida_mas | F1: iman_mult | G1: regen_mas | H1: blindaje_mult | I1: blindaje_mas | J1: velocidad_mult | K1: peso_mult | L1: recarga_mult | M1: xp_mult | N1: arma_inicial | O1: habilidad | P1: habilidad_txt
A2: Identificador (no cambiar) | B2: Nombre (referencia) | C2: Precio en tornillos (0 = de serie o por logro) | D2: Multiplicador del daño del equipo (1 = sin cambio) | E2: Vida máxima extra (suma) | F2: Multiplicador del radio del imán | G2: Regeneración extra por segundo (suma) | H2: Multiplicador del daño recibido (0,88 = recibe 12% menos) | I2: Suma al blindaje (−0,1 = recibe 10% más) | J2: Multiplicador de velocidad | K2: Multiplicador de masa del auto | L2: Multiplicador del tiempo de recarga de armas (1,1 = 10% más lentas) | M2: Multiplicador de XP | N2: Arma con la que arranca (id de la hoja armas)
A3: soldadito | B3: El Sargento Sin Pensión | C3: 0 | D3: 1.1 | E3: 10 | F3: 0.9 | G3: 0 | H3: 1 | I3: 0 | J3: 1 | K3: 1 | L3: 1 | M3: 1 | N3: gomitas | O3: bombardeo | P3: Orden del día: petardos. Lluvia de petardos alrededor del auto.
A4: muneca | B4: La Divorciada de Trapo | C4: 450 | D4: 1 | E4: -20 | F4: 1.25 | G4: 1 | H4: 1 | I4: 0 | J4: 1 | K4: 1 | L4: 1 | M4: 1 | N4: gomitas | O4: escudo | P4: Remiendo exprés: escudo de 3 s que cura 30% de la vida.
A5: robot | B5: El Robot en Crisis | C5: 650 | D5: 1 | E5: 0 | F5: 1 | G5: 0 | H5: 0.88 | I5: 0 | J5: 0.92 | K5: 1 | L5: 1 | M5: 1 | N5: tesla | O5: lenta | P5: Sobreclock: el mundo va al 40% durante 3 s y el auto no se frena.
A6: dino | B6: El Rex Jubilado | C6: 0 | D6: 1 | E6: 40 | F6: 1 | G6: 0 | H6: 1 | I6: 0 | J6: 1 | K6: 1.25 | L6: 1.1 | M6: 1 | N6: gomitas | O6: emp | P6: Rugido jubilado: aturde 2 s a los enemigos cercanos (jefes no).
A7: figura | B7: El Mega Macho | C7: 0 | D7: 1 | E7: 0 | F7: 1 | G7: 0 | H7: 1 | I7: -0.1 | J7: 1.06 | K7: 1 | L7: 1 | M7: 1.15 | N7: petardos | O7: turbo | P7: Exhibición de fuerza: 4 s de turbo con embestida reforzada, a puro músculo hueco.
A8: abuela | B8: La Abuela de Porcelana | C8: 800 | D8: 1 | E8: -15 | F8: 1 | G8: 0 | H8: 1 | I8: 0.12 | J8: 0.95 | K8: 1 | L8: 1 | M8: 1 | N8: yoyo | O8: escudo | P8: Té de las cinco: escudo de 3 s que cura 30% de la vida, con galletitas.
A9: astronauta | B9: El Astronauta de Plástico | C9: 1000 | D9: 1 | E9: -10 | F9: 1.3 | G9: 0 | H9: 1 | I9: 0 | J9: 1.08 | K9: 1 | L9: 1 | M9: 1 | N9: canicas | O9: lenta | P9: Gravedad cero: el mundo va al 40% durante 3 s y el auto no se frena.
A10: dinogoma | B10: El Dinosaurio de Goma Mordida | C10: 0 | D10: 1.2 | E10: 0 | F10: 1 | G10: 0 | H10: 1 | I10: 0 | J10: 1 | K10: 1 | L10: 1.1 | M10: 1 | N10: trompo | O10: bombardeo | P10: Mordisco de perro: lluvia de petardos alrededor del auto.
A11: rusa | B11: La Muñeca Rusa Desconfiada | C11: 1200 | D11: 0.9 | E11: 25 | F11: 1 | G11: 0 | H11: 1 | I11: 0 | J11: 0.95 | K11: 1.15 | L11: 1 | M11: 1.1 | N11: helado | O11: turbo | P11: Sorpresa por dentro: 4 s de turbo con embestida reforzada, por si acaso.

Sheet precios
A1: id | B1: tipo | C1: nombre | D1: efecto | E1: nivel1 | F1: nivel2 | G1: nivel3 | H1: nivel4 | I1: nivel5 | J1: nivel6 | K1: nivel7 | L1: nivel8 | M1: nivel9 | N1: nivel10
A2: Identificador (no cambiar) | B2: mejora, habilidad, arma, zona o pieza (referencia) | C2: Nombre (referencia) | D2: Efecto por nivel de la mejora: Chasis +vida, Piñón +fracción de daño, Motor +fracción de velocidad, Imán +fracción, Contador de tuercas +fracción de XP, Placa de lata +fracción de blindaje, Cinta aisladora +vida/s, Nafta de encendedor +fracción de turbo (recarga y duración), Paragolpes de fierro +fracción de daño al embestir, Gatillo engrasado −fracción de recarga de armas (0 = fijo; habilidades: ver ritmo habilidad_cd_nivel y habilidad_efecto_nivel) | E2: Precio en tornillos del nivel 1 (vacío = ese nivel no existe) | F2: Precio en tornillos del nivel 2 (vacío = ese nivel no existe) | G2: Precio en tornillos del nivel 3 (vacío = ese nivel no existe) | H2: Precio en tornillos del nivel 4 (vacío = ese nivel no existe) | I2: Precio en tornillos del nivel 5 (vacío = ese nivel no existe) | J2: Precio en tornillos del nivel 6 (vacío = ese nivel no existe) | K2: Precio en tornillos del nivel 7 (vacío = ese nivel no existe) | L2: Precio en tornillos del nivel 8 (vacío = ese nivel no existe) | M2: Precio en tornillos del nivel 9 (vacío = ese nivel no existe) | N2: Precio en tornillos del nivel 10 (vacío = ese nivel no existe)
A3: hp | B3: mejora | C3: Chasis reforzado | D3: 10 | E3: 20 | F3: 40 | G3: 60 | H3: 80 | I3: 100 | J3: 180 | K3: 275 | L3: 385 | M3: 515 | N3: 660
A4: dmg | B4: mejora | C4: Piñón afilado | D4: 0.1 | E4: 20 | F4: 40 | G4: 60 | H4: 80 | I4: 100 | J4: 180 | K4: 275 | L4: 385 | M4: 515 | N4: 660
A5: spd | B5: mejora | C5: Motor rebobinado | D5: 0.04 | E5: 20 | F5: 40 | G5: 60 | H5: 80 | I5: 100 | J5: 180 | K5: 275 | L5: 385 | M5: 515 | N5: 660
A6: mag | B6: mejora | C6: Imán de parlante | D6: 0.1 | E6: 20 | F6: 40 | G6: 60 | H6: 80 | I6: 100 | J6: 180 | K6: 275 | L6: 385 | M6: 515 | N6: 660
A7: arm | B7: mejora | C7: Placa de lata | D7: 0.02 | E7: 20 | F7: 40 | G7: 60 | H7: 80 | I7: 100 | J7: 180 | K7: 275 | L7: 385 | M7: 515 | N7: 660
A8: reg | B8: mejora | C8: Cinta aisladora | D8: 0.1 | E8: 20 | F8: 40 | G8: 60 | H8: 80 | I8: 100 | J8: 180 | K8: 275 | L8: 385 | M8: 515 | N8: 660
A9: tur | B9: mejora | C9: Nafta de encendedor | D9: 0.06 | E9: 20 | F9: 40 | G9: 60 | H9: 80 | I9: 100 | J9: 180 | K9: 275 | L9: 385 | M9: 515 | N9: 660
A10: ram | B10: mejora | C10: Paragolpes de fierro | D10: 0.08 | E10: 20 | F10: 40 | G10: 60 | H10: 80 | I10: 100 | J10: 180 | K10: 275 | L10: 385 | M10: 515 | N10: 660
A11: cdr | B11: mejora | C11: Gatillo engrasado | D11: 0.02 | E11: 25 | F11: 50 | G11: 75 | H11: 100 | I11: 125 | J11: 225 | K11: 345 | L11: 480 | M11: 645 | N11: 825
A12: xp | B12: mejora | C12: Contador de tuercas | D12: 0.05 | E12: 80 | F12: 180 | G12: 320 | H12: 500
A13: reroll | B13: mejora | C13: Dado cargado | D13: 0 | E13: 100 | F13: 250 | G13: 450
A14: extra | B14: mejora | C14: Caja de repuestos | D14: 0 | E14: 500
A15: revive | B15: mejora | C15: Batería de reserva | D15: 0 | E15: 600 | F15: 1800
A16: cards | B16: mejora | C16: Cuarta ranura | D16: 0 | E16: 2200
A17: zona_garaje | B17: zona | C17: Garaje de la casa | D17: 0 | E17: 700
A18: zona_jardin | B18: zona | C18: Jardín delantero | D18: 0 | E18: 1000
A19: zona_pileta | B19: zona | C19: La pileta vacía | D19: 0 | E19: 1800
A20: zona_desvan | B20: zona | C20: Desván de los juguetes rotos | D20: 0 | E20: 1500
A21: pieza_wing_alto | B21: pieza | C21: Alerón alto | D21: 0 | E21: 60
A22: pieza_wing_doble | B22: pieza | C22: Biplano | D22: 0 | E22: 110
A23: pieza_decal_numero | B23: pieza | C23: Calco Número | D23: 0 | E23: 40
A24: pieza_decal_rayo | B24: pieza | C24: Calco Rayo | D24: 0 | E24: 60
A25: pieza_decal_damero | B25: pieza | C25: Calco Damero | D25: 0 | E25: 90
A26: pieza_lamp_ambar | B26: pieza | C26: Faro Ámbar | D26: 0 | E26: 50
A27: pieza_lamp_cian | B27: pieza | C27: Faro Cian | D27: 0 | E27: 80
... A30: pieza_exhaust_chimenea | B30: pieza | C30: Escape Chimeneas | D30: 0 | E30: 100
A31: hab_bombardeo | B31: habilidad | C31: Bombardeo de petardos | D31: 0 | E31: 60 | F31: 150 | G31: 300 | H31: 550
A32: hab_escudo | B32: habilidad | C32: Escudo que cura | D32: 0 | E32: 60 | F32: 150 | G32: 300 | H32: 550
A33: hab_emp | B33: habilidad | C33: Pulso EMP | D33: 0 | E33: 60 | F33: 150 | G33: 300 | H33: 550
A34: hab_turbo | B34: habilidad | C34: Turbo de plaza | D34: 0 | E34: 60 | F34: 150 | G34: 300 | H34: 550
A35: hab_lenta | B35: habilidad | C35: Cámara lenta | D35: 0 | E35: 60 | F35: 150 | G35: 300 | H35: 550
A36: arma_clips | B36: arma | C36: Lanzaclips | D36: 0 | E36: 150
A37: arma_chispero | B37: arma | C37: Chispero | D37: 0 | E37: 200
A38: arma_agua | B38: arma | C38: Pistola de agua | D38: 0 | E38: 200
A39: arma_yoyo | B39: arma | C39: Yoyó | D39: 0 | E39: 250
A40: arma_bengalas | B40: arma | C40: Bengalas | D40: 0 | E40: 250
A41: arma_regla | B41: arma | C41: Regla | D41: 0 | E41: 300
A42: arma_petardos | B42: arma | C42: Petardos | D42: 0 | E42: 300
...

Sheet plagas
A1: id | B1: nombre | C1: mult_hormiga | D1: mult_friccion | E1: mult_escupidora | F1: mult_robot | G1: mult_polilla | H1: mult_escarabajo | I1: mult_grillo | J1: mult_mosca | K1: mult_babosa | L1: desde_hormiga | M1: desde_friccion | N1: desde_escupidora | O1: desde_robot | P1: desde_polilla | Q1: desde_escarabajo | R1: desde_grillo | S1: desde_mosca | T1: desde_babosa
A2: Identificador (no cambiar) | B2: Nombre (referencia) | C2: Multiplicador del peso de aparición: hormiga | D2: Multiplicador del peso de aparición: friccion | E2: Multiplicador del peso de aparición: escupidora | F2: Multiplicador del peso de aparición: robot | G2: Multiplicador del peso de aparición: polilla | H2: Multiplicador del peso de aparición: escarabajo | L2: Minuto desde el que aparece hormiga (−1 = su minuto normal) | M2: Minuto desde el que aparece friccion (−1 = su minuto normal) | N2: Minuto desde el que aparece escupidora (−1 = su minuto normal) | O2: Minuto desde el que aparece robot (−1 = su minuto normal) | P2: Minuto desde el que aparece polilla (−1 = su minuto normal) | Q2: Minuto desde el que aparece escarabajo (−1 = su minuto normal)
A3: plaga_hormigas | B3: PLAGA DE HORMIGAS | C3: 1.6 | D3: 0.8 | E3: 1 | F3: 1 | G3: 1 | H3: 1 | I3: 0.8 | J3: 1.5 | K3: 1 | L3: -1 | M3: -1 | N3: -1 | O3: -1 | P3: -1 | Q3: -1 | R3: -1 | S3: -1 | T3: -1
A4: plaga_juguetes | B4: INVASIÓN DE JUGUETES | C4: 0.6 | D4: 2 | E4: 1 | F4: 1.8 | G4: 1 | H4: 1 | I4: 1.5 | J4: 0.6 | K4: 1 | L4: -1 | M4: -1 | N4: -1 | O4: 0.8 | P4: -1 | Q4: -1 | R4: -1 | S4: -1 | T4: -1
A5: plaga_acido | B5: LLUVIA DE ÁCIDO | C5: 1 | D5: 1 | E5: 2.4 | F5: 1 | G5: 1 | H5: 1 | I5: 1 | J5: 1.2 | K5: 1 | L5: -1 | M5: -1 | N5: 0.6 | O5: -1 | P5: -1 | Q5: -1 | R5: -1 | S5: -1 | T5: -1
A6: plaga_escarabajos | B6: ESCARABAJOS TEMPRANOS | C6: 1 | D6: 1 | E6: 1 | F6: 1 | G6: 1 | H6: 1.5 | I6: 0.8 | J6: 0.8 | K6: 1 | L6: -1 | M6: -1 | N6: -1 | O6: -1 | P6: -1 | Q6: 2.5 | R6: -1 | S6: -1 | T6: -1
A7: plaga_mixto | B7: PATIO MIXTO | C7: 0.8 | D7: 1.3 | E7: 1.3 | F7: 1.3 | G7: 1 | H7: 1 | I7: 1.2 | J7: 1.2 | K7: 1 | L7: -1 | M7: -1 | N7: 1 | O7: 1 | P7: -1 | Q7: -1 | R7: -1 | S7: -1 | T7: -1

Sheet armas_extra
A1: id | B1: valor | C1: descripcion
A2: Identificador (no cambiar) | B2: Número: editar solo esta columna | C2: Qué controla
A3: gomitas_rebotes_evo | B3: 3 | C3: Rebotes entre enemigos de la gomita evolucionada
A4: gomitas_rebote_alcance | B4: 12 | C4: Alcance (m) con el que busca el siguiente enemigo al rebotar
A5: gomitas_rebote_vida_s | B5: 0.8 | C5: Segundos de vida que le quedan a la gomita tras un rebote
A6: gomitas_abanico | B6: 0.16 | C6: Separación (rad) entre gomitas cuando salen varias
A7: gomitas_empuje | B7: 2 | C7: Empuje de cada gomita
A8: clips_golpe_recarga_s | B8: 0.35 | C8: Segundos entre golpes de un clip al mismo enemigo
A9: clips_empuje | B9: 3 | C9: Empuje de cada clip
A10: chispero_intervalo_s | B10: 0.09 | C10: Segundos entre manchas de fuego (más corto = más fuegos superpuestos)
A11: chispero_vel_min | B11: 4 | C11: Velocidad mínima (m/s) para que el auto deje fuego
A12: petardos_racimo_n | B12: 4 | C12: Explosiones extra de la Bomba de Racimo (evolución)
A13: petardos_racimo_radio | B13: 0.7 | C13: Radio de cada explosión extra, como fracción de la principal
A14: petardos_racimo_dano | B14: 0.6 | C14: Daño de cada explosión extra, como fracción de la principal
... A122: vapor_ralentiza_s | B122: 0.5 | C122: Vapor: segundos de ralentización en la zona

Sheet ritmo
A1: id | B1: valor | C1: descripcion
A2: Identificador (no cambiar) | B2: Número: editar solo esta columna | C2: Qué controla
A3: coop_vida_por_jugador | B3: 0.6 | C3: ENCORE cooperativo: vida de bichos y jefes × (1 + valor × (jugadores - 1)); compensa las copias de armas de cada compañero
A4: coop_ritmo_por_jugador | B4: 0.35 | C4: ENCORE cooperativo: aparición y tope de vivos de bichos × (1 + valor × (jugadores - 1))
A5: dureza_cantidad | B5: 0.5 | C5: Multiplicador de la cantidad de bichos normales (aparición, tope de vivos y enjambres)
A6: dureza_vida | B6: 2 | C6: Multiplicador de vida de los bichos normales (no afecta a los jefes)
A7: dureza_dano | B7: 3.2 | C7: Multiplicador del daño por contacto de los bichos normales
A8: oferta_peso_propia | B8: 2.5 | C8: Cartas de nivel: peso de sorteo de subir un arma que ya se tiene (1 = igual que una pasiva)
A9: oferta_peso_nueva | B9: 0.6 | C9: Cartas de nivel: peso de sorteo de un arma nueva (solo sale si hay ranura libre)
A10: dureza_xp | B10: 1.62 | C10: Multiplicador de las tuercas de XP que sueltan los bichos normales
A11: xp_temprana_s | B11: 180 | C11: Hasta este segundo de partida la XP recogida se multiplica por xp_temprana_mult (rampa lenta)
A12: xp_temprana_mult | B12: 0.78 | C12: Multiplicador de XP ganada en los primeros xp_temprana_s segundos
A13: vida_escala_seg | B13: 200 | C13: Los bichos normales ganan +100% de vida cada tantos segundos: vida × (1 + t / valor)
A14: tope_vivos_base | B14: 18 | C14: Bichos normales vivos permitidos al empezar (antes de la dureza)
... A196: luna_xp_mult | B196: 0.65 | C196: Luna: multiplicador de la experiencia de los bichos normales (en la esfera todos terminan llegando al auto: con la misma experiencia por bicho se sube mucho más rápido que en el patio)

Sheet ataques
A1: id | B1: valor | C1: descripcion
A2: Identificador (no cambiar) | B2: Número: editar solo esta columna | C2: Qué controla
A3: bicho_lento_mult | B3: 0.45 | C3: Velocidad de un bicho normal empapado o enfriado (multiplicador)
A4: jefe_lento_mult | B4: 0.8 | C4: Velocidad de un jefe empapado o enfriado (multiplicador)
A5: fase2_vida | B5: 0.5 | C5: Un jefe pasa a fase 2 con menos de esta fracción de su vida
A6: segunda_barra_vida | B6: 0.5 | C6: Jefe final: al vaciar la primera barra ruge y se llena una segunda con esta fracción de su vida
A7: segunda_barra_dano | B7: 1.5 | C7: Jefe final en la segunda barra: multiplicador del daño que hace al auto
A8: fase2_vel | B8: 1.2 | C8: Fase 2: multiplicador de velocidad
A9: fase2_rugido_s | B9: 1.7 | C9: Fase 2: segundos que ruge quieto
A10: acido_dano | B10: 7 | C10: Daño de un escupitajo o una tuerca al auto
A11: acido_vel | B11: 16 | C11: Velocidad (m/s) de escupitajos y tuercas
A12: salto_dano | B12: 25 | C12: Daño del aplastón de los saltos (tarántula, Eulalio, Felipe) si el auto está dentro del radio
A13: salto_radio | B13: 11 | C13: Radio (m) del aplastón de los saltos
A14: salto_aplasta_radio | B14: 10 | C14: Radio (m) en el que el aplastón liquida a los bichos normales
... A274: gusano_fase2_seguidas | B274: 2 | C274: Luna, gusano en la segunda barra: salidas seguidas (la siguiente sin esperar ni perseguir, con el aviso a la mitad)

Sheet duelo
A1: id | B1: valor | C1: descripcion
A2: Identificador (no cambiar) | B2: Número: editar solo esta columna | C2: Qué controla
A3: hp_base | B3: 100 | C3: Vida base antes del bonus de chasis (modo Demolición)
A4: melee_cd_s | B4: 0.55 | C4: Segundos de cooldown por par atacante–víctima
A5: melee_vel_coef | B5: 1.15 | C5: Multiplicador de daño por velocidad relativa normalizada (0–1)
A6: melee_masa_coef | B6: 0.08 | C6: Término de masa: (masa_atacante_kg / 5) × este coeficiente
A7: warn_traccion_mul | B7: 0.95 | C7: Multiplicador de tracción si el loadout confirmado estaba en WARN
A8: asalto_objetivo_s | B8: 120 | C8: Duración objetivo de un asalto (tuning; no es límite duro)
A9: volcado_vuln_mul | B9: 1.25 | C9: Multiplicador de daño recibido mientras el robot está volcado
A10: flip_cd_s | B10: 1.35 | C10: Cooldown del botón enderezar tras volcado (modo Demolición)
A11: phys_grip_fwd_k | B11: 1.05 | C11: Coef. frenado longitudinal sin acelerador (× grip × masa)
A12: phys_grip_lat_k | B12: 2.65 | C12: Coef. frenado lateral (× grip × masa)
A13: phys_grip_fwd_min_spd | B13: 0.35 | C13: |vel longitudinal| mínima para grip longitudinal
A14: phys_grip_lat_min_spd | B14: 0.08 | C14: |vel lateral| mínima para grip lateral
... A36: part_wear_mul | B36: 0.5 | C36: Fracción del daño melee que desgasta integridad del bloque impactado (fabricación)

Sheet duelo_bloques
A1: id | B1: nombre | C1: cat | D1: sx | E1: sy | F1: sz | G1: masa_kg | H1: hp | I1: wheel_count | J1: vel_max_mul | K1: traccion_mul | L1: dano_base | M1: push_mul | N1: rpm_max | O1: rpm_carga_s | P1: knock_up_n | Q1: cog_y_m
A2: Identificador (no cambiar) | B2: Nombre en UI | C2: chasis | movimiento | arma | especial | cosmetico | D2: Footprint X (celdas) | E2: Footprint Y (celdas) | F2: Footprint Z (celdas) | G2: Masa (kg) | H2: Vida aportada al HP global | I2: Cuántas ruedas aporta (oruga = 2) | J2: Multiplicador de velocidad | K2: Multiplicador de tracción | L2: Daño melee (armas) | M2: Empuje | N2: RPM máx (trompo) | O2: Carga RPM (s) | P2: Knock-up sierra | Q2: Offset CoG Y local (m)
A3: chapa | B3: Chapa | C3: chasis | D3: 1 | E3: 1 | F3: 1 | G3: 0.35 | H3: 8 | I3: 0 | J3: 1 | K3: 1 | L3: 0 | M3: 0 | N3: 0 | O3: 0 | P3: 0 | Q3: 0.12
A4: cuna_blk | B4: Cuña | C4: chasis | D4: 1 | E4: 1 | F4: 2 | G4: 0.55 | H4: 10 | I4: 0 | J4: 1 | K4: 1.05 | L4: 0 | M4: 0 | N4: 0 | O4: 0 | P4: 0 | Q4: 0.08
A5: plancha_blk | B5: Plancha | C5: chasis | D5: 2 | E5: 1 | F5: 2 | G5: 0.45 | H5: 6 | I5: 0 | J5: 1.05 | K5: 0.95 | L5: 0 | M5: 0 | N5: 0 | O5: 0 | P5: 0 | Q5: 0.06
A6: chapa_u | B6: Chapa U | C6: chasis | D6: 2 | E6: 1 | F6: 1 | G6: 0.4 | H6: 7 | I6: 0 | J6: 1 | K6: 1 | L6: 0 | M6: 0 | N6: 0 | O6: 0 | P6: 0 | Q6: 0.1
A7: rueda_std | B7: Rueda estándar | C7: movimiento | D7: 1 | E7: 1 | F7: 1 | G7: 0.1 | H7: 4 | I7: 1 | J7: 1 | K7: 1 | L7: 0 | M7: 0 | N7: 0 | O7: 0 | P7: 0 | Q7: 0.05
A8: rueda_gig | B8: Rueda gigante | C8: movimiento | D8: 1 | E8: 1 | F8: 1 | G8: 0.22 | H8: 5 | I8: 1 | J8: 0.9 | K8: 1.2 | L8: 0 | M8: 0 | N8: 0 | O8: 0 | P8: 0 | Q8: 0.12
A9: oruga | B9: Oruga | C9: movimiento | D9: 1 | E9: 1 | F9: 2 | G9: 0.55 | H9: 8 | I9: 2 | J9: 0.8 | K9: 1.35 | L9: 0 | M9: 0 | N9: 0 | O9: 0 | P9: 0 | Q9: 0.08
A10: trompo | B10: Trompo | C10: arma | D10: 1 | E10: 1 | F10: 1 | G10: 0.8 | H10: 6 | I10: 0 | J10: 1 | K10: 1 | L10: 5 | M10: 0.6 | N10: 1 | O10: 0.35 | P10: 0 | Q10: 0.2
A11: sierra | B11: Sierra | C11: arma | D11: 1 | E11: 1 | F11: 1 | G11: 0.7 | H11: 5 | I11: 0 | J11: 1 | K11: 1 | L11: 7 | M11: 0.3 | N11: 0 | O11: 0 | P11: 2.2 | Q11: 0.18
A12: pala | B12: Pala | C12: arma | D12: 1 | E12: 1 | F12: 1 | G12: 1.2 | H12: 7 | I12: 0 | J12: 1 | K12: 1 | L12: 2 | M12: 2.15 | N12: 0 | O12: 0 | P12: 0 | Q12: 0.15
A13: asiento_rc | B13: Asiento RC | C13: especial | D13: 1 | E13: 1 | F13: 1 | G13: 0.15 | H13: 5 | I13: 0 | J13: 1 | K13: 1 | L13: 0 | M13: 0 | N13: 0 | O13: 0 | P13: 0 | Q13: 0.14
A14: puerta | B14: Puerta | C14: cosmetico | D14: 1 | E14: 1 | F14: 1 | G14: 0.08 | H14: 2 | I14: 0 | J14: 1 | K14: 1 | L14: 0 | M14: 0 | N14: 0 | O14: 0 | P14: 0 | Q14: 0.12
A15: muneco | B15: Muñeco | C15: cosmetico | D15: 1 | E15: 1 | F15: 1 | G15: 0.05 | H15: 1 | I15: 0 | J15: 1 | K15: 1 | L15: 0 | M15: 0 | N15: 0 | O15: 0 | P15: 0 | Q15: 0.16

Sheet duelo_chasis
A1: id | B1: nombre | C1: masa_kg | D1: hp_bonus | E1: traccion_mul | F1: vel_max_mul | G1: cog_y_m
A2: Identificador (no cambiar) | B2: Nombre en UI (referencia) | C2: Masa del chasis (kg) para física y barras | D2: Vida extra sumada a duelo.hp_base | E2: Multiplicador de tracción (1 = referencia) | F2: Multiplicador de velocidad máxima | G2: Centro de gravedad Y (m) para preview y física
A3: caja | B3: Caja | C3: 3 | D3: 30 | E3: 1 | F3: 0.92 | G3: 0.4
A4: cuna | B4: Cuña | C4: 2.2 | D4: -10 | E4: 1.1 | F4: 1 | G4: 0.22
A5: plancha | B5: Plancha | C5: 1.8 | D5: -20 | E5: 0.95 | F5: 1.05 | G5: 0.3

Sheet duelo_ruedas
A1: id | B1: nombre | C1: masa_kg | D1: vel_max_mul | E1: traccion_mul | F1: lift_m
A2: Identificador (no cambiar) | B2: Nombre en UI (referencia) | C2: Masa (kg) | D2: Multiplicador de velocidad máxima | E2: Multiplicador de tracción | F2: Metros que eleva el chasis (gigantes)
A3: estandar | B3: Estándar | C3: 0.4 | D3: 1 | E3: 1 | F3: 0
A4: gigantes | B4: Gigantes | C4: 0.9 | D4: 0.9 | E4: 1.2 | F4: 0.15
A5: orugas | B5: Orugas | C5: 1.1 | D5: 0.8 | E5: 1.35 | F5: 0

Sheet duelo_armas
A1: id | B1: nombre | C1: masa_kg | D1: dano_base | E1: push_mul | F1: rpm_max | G1: rpm_carga_s | H1: knock_up_n
A2: Identificador (no cambiar) | B2: Nombre en UI (referencia) | C2: Masa (kg) | D2: Daño base melee antes de velocidad/RPM | E2: Multiplicador de empuje Havok | F2: RPM máxima (0 = no aplica) | G2: Segundos para cargar de 0 a RPM máx (trompo; 0 = no aplica) | H2: Impulso vertical en sierra (0 = no aplica)
A3: trompo | B3: Trompo | C3: 0.8 | D3: 5 | E3: 0.6 | F3: 1 | G3: 0.35 | H3: 0
A4: sierra | B4: Sierra | C4: 0.7 | D4: 7 | E4: 0.3 | F4: 0 | G4: 0 | H4: 2.2
A5: pala | B5: Pala | C5: 1.2 | D5: 2 | E5: 2.15 | F5: 0 | G5: 0 | H5: 0

Sheet duelo_rival
A1: id | B1: nombre | C1: chasis_id | D1: ruedas_id | E1: arma_id | F1: cuerpo_color | G1: bandas_color | H1: pala_color
A2: Identificador del rival (no cambiar) | B2: Nombre en UI | C2: Id en duelo_chasis | D2: Id en duelo_ruedas | E2: Id en duelo_armas | F2: Color hex cuerpo | G2: Color hex bandas/orugas | H2: Color hex del arma
A3: cuna_industrial | B3: CUÑA INDUSTRIAL | C3: cuna | D3: orugas | E3: pala | F3: #2a2d32 | G3: #e85d04 | H3: #8a9098

Sheet Golpes para matar
A1: Golpes para matar
A2: Cuántos golpes de cada arma (a nivel 1 y a nivel 5, sin evolución) y cuántas embestidas hacen falta para matar a cada bicho. Se recalcula con las hojas enemigos, armas, autos y ritmo.
A4: Segundo de la partida (la vida de los bichos normales sube con el tiempo) | B4: 0
A5: Multiplicador de daño del equipo (pasivas Lupa, mejoras del taller, piloto) | B5: 1
A6: Auto de la embestida (id de la hoja autos) | B6: buggy
A7: Velocidad típica de embestida hacia el enemigo (m/s) | B7: 12
A8: Multiplicador extra de embestida (turbo 1,3; Lápiz-lanza nivel 5: 2,75) | B8: 1
D9: arma | E9: =INDEX(armas!$B$3:$B$500,MATCH(E$10,armas!$A$3:$A$500,0)) | F9: =INDEX(armas!$B$3:$B$500,MATCH(F$10,armas!$A$3:$A$500,0)) | G9: =INDEX(armas!$B$3:$B$500,MATCH(G$10,armas!$A$3:$A$500,0)) | H9: =INDEX(armas!$B$3:$B$500,MATCH(H$10,armas!$A$3:$A$500,0)) | I9: =INDEX(armas!$B$3:$B$500,MATCH(I$10,armas!$A$3:$A$500,0)) | J9: =INDEX(armas!$B$3:$B$500,MATCH(J$10,armas!$A$3:$A$500,0)) | K9: =INDEX(armas!$B$3:$B$500,MATCH(K$10,armas!$A$3:$A$500,0)) | L9: =INDEX(armas!$B$3:$B$500,MATCH(L$10,armas!$A$3:$A$500,0)) | ... AZ9: =INDEX(armas!$B$3:$B$500,MATCH(AZ$10,armas!$A$3:$A$500,0)) | BA9: Embestida
D10: id del arma | E10: gomitas | F10: gomitas | G10: clips | H10: clips | I10: chispero | J10: chispero | K10: petardos | L10: petardos | M10: tesla | N10: tesla | O10: agua | P10: agua | Q10: yoyo | R10: yoyo | S10: bengalas | T10: bengalas | U10: regla | V10: regla | W10: helado | X10: helado | Y10: bocina | Z10: bocina | AA10: trompo | AB10: trompo | AC10: tuercas | AD10: tuercas | AE10: bobinas | AF10: bobinas | AG10: ventilador | AH10: ventilador | AI10: canicas | AJ10: canicas | AK10: burbujas | AL10: burbujas | AM10: matamoscas | AN10: matamoscas | AO10: dardos | AP10: dardos | AQ10: chapitas | AR10: chapitas | AS10: paraguas | AT10: paraguas | AU10: cohete | AV10: cohete | AW10: serpentinas | AX10: serpentinas | AY10: tambor | AZ10: tambor | BA10: embestida
D11: nivel | E11: 1 | F11: 5 | G11: 1 | H11: 5 | I11: 1 | J11: 5 | K11: 1 | L11: 5 | M11: 1 | N11: 5 | O11: 1 | P11: 5 | Q11: 1 | R11: 5 | S11: 1 | T11: 5 | U11: 1 | V11: 5 | W11: 1 | X11: 5 | Y11: 1 | Z11: 5 | AA11: 1 | AB11: 5 | AC11: 1 | AD11: 5 | AE11: 1 | AF11: 5 | AG11: 1 | AH11: 5 | AI11: 1 | AJ11: 5 | AK11: 1 | AL11: 5 | AM11: 1 | AN11: 5 | AO11: 1 | AP11: 5 | AQ11: 1 | AR11: 5 | AS11: 1 | AT11: 5 | AU11: 1 | AV11: 5 | AW11: 1 | AX11: 5 | AY11: 1 | AZ11: 5
A12: id | B12: nombre | C12: tipo | D12: vida efectiva / daño por golpe | E12: =(INDEX(armas!$D$3:$D$500,MATCH(E$10,armas!$A$3:$A$500,0))+INDEX(armas!$E$3:$E$500,MATCH(E$10,armas!$A$3:$A$500,0))*E$11)*$B$5 | F12: =(INDEX(armas!$D$3:$D$500,MATCH(F$10,armas!$A$3:$A$500,0))+INDEX(armas!$E$3:$E$500,MATCH(F$10,armas!$A$3:$A$500,0))*F$11)*$B$5 | G12: =(INDEX(armas!$D$3:$D$500,MATCH(G$10,armas!$A$3:$A$500,0))+INDEX(armas!$E$3:$E$500,MATCH(G$10,armas!$A$3:$A$500,0))*G$11)*$B$5 | H12: =(INDEX(armas!$D$3:$D$500,MATCH(H$10,armas!$A$3:$A$500,0))+INDEX(armas!$E$3:$E$500,MATCH(H$10,armas!$A$3:$A$500,0))*H$11)*$B$5 | I12: =(INDEX(armas!$D$3:$D$500,MATCH(I$10,armas!$A$3:$A$500,0))+INDEX(armas!$E$3:$E$500,MATCH(I$10,armas!$A$3:$A$500,0))*I$11)*$B$5 | J12: =(INDEX(armas!$D$3:$D$500,MATCH(J$10,armas!$A$3:$A$500,0))+INDEX(armas!$E$3:$E$500,MATCH(J$10,armas!$A$3:$A$500,0))*J$11)*$B$5 | K12: =(INDEX(armas!$D$3:$D$500,MATCH(K$10,armas!$A$3:$A$500,0))+INDEX(armas!$E$3:$E$500,MATCH(K$10,armas!$A$3:$A$500,0))*K$11)*$B$5 | L12: =(INDEX(armas!$D$3:$D$500,MATCH(L$10,armas!$A$3:$A$500,0))+INDEX(armas!$E$3:$E$500,MATCH(L$10,armas!$A$3:$A$500,0))*L$11)*$B$5 | ... AZ12: =(INDEX(armas!$D$3:$D$500,MATCH(AZ$10,armas!$A$3:$A$500,0))+INDEX(armas!$E$3:$E$500,MATCH(AZ$10,armas!$A$3:$A$500,0))*AZ$11)*$B$5 | BA12: =$B$7*INDEX(autos!$I$3:$I$500,MATCH($B$6,autos!$A$3:$A$500,0))*$B$8*$B$5
A13: hormiga | B13: =INDEX(enemigos!$B$3:$B$500,MATCH($A13,enemigos!$A$3:$A$500,0)) | C13: =INDEX(enemigos!$C$3:$C$500,MATCH($A13,enemigos!$A$3:$A$500,0)) | D13: =IF($C13="bicho",INDEX(enemigos!$D$3:$D$500,MATCH($A13,enemigos!$A$3:$A$500,0))*INDEX(ritmo!$B$3:$B$500,MATCH("dureza_vida",ritmo!$A$3:$A$500,0))*(1+$B$4/INDEX(ritmo!$B$3:$B$500,MATCH("vida_escala_seg",ritmo!$A$3:$A$500,0))),INDEX(enemigos!$D$3:$D$500,MATCH($A13,enemigos!$A$3:$A$500,0))) | E13: =IF(E$12>0,ROUNDUP($D13/E$12,0),"-") | F13: =IF(F$12>0,ROUNDUP($D13/F$12,0),"-") | G13: =IF(G$12>0,ROUNDUP($D13/G$12,0),"-") | H13: =IF(H$12>0,ROUNDUP($D13/H$12,0),"-") | I13: =IF(I$12>0,ROUNDUP($D13/I$12,0),"-") | J13: =IF(J$12>0,ROUNDUP($D13/J$12,0),"-") | K13: =IF(K$12>0,ROUNDUP($D13/K$12,0),"-") | L13: =IF(L$12>0,ROUNDUP($D13/L$12,0),"-") | ... BA13: =IF(BA$12>0,ROUNDUP($D13/BA$12,0),"-")
A14: escupidora | B14: =INDEX(enemigos!$B$3:$B$500,MATCH($A14,enemigos!$A$3:$A$500,0)) | C14: =INDEX(enemigos!$C$3:$C$500,MATCH($A14,enemigos!$A$3:$A$500,0)) | D14: =IF($C14="bicho",INDEX(enemigos!$D$3:$D$500,MATCH($A14,enemigos!$A$3:$A$500,0))*INDEX(ritmo!$B$3:$B$500,MATCH("dureza_vida",ritmo!$A$3:$A$500,0))*(1+$B$4/INDEX(ritmo!$B$3:$B$500,MATCH("vida_escala_seg",ritmo!$A$3:$A$500,0))),INDEX(enemigos!$D$3:$D$500,MATCH($A14,enemigos!$A$3:$A$500,0))) | E14: =IF(E$12>0,ROUNDUP($D14/E$12,0),"-") | F14: =IF(F$12>0,ROUNDUP($D14/F$12,0),"-") | G14: =IF(G$12>0,ROUNDUP($D14/G$12,0),"-") | H14: =IF(H$12>0,ROUNDUP($D14/H$12,0),"-") | I14: =IF(I$12>0,ROUNDUP($D14/I$12,0),"-") | J14: =IF(J$12>0,ROUNDUP($D14/J$12,0),"-") | K14: =IF(K$12>0,ROUNDUP($D14/K$12,0),"-") | L14: =IF(L$12>0,ROUNDUP($D14/L$12,0),"-") | ... BA14: =IF(BA$12>0,ROUNDUP($D14/BA$12,0),"-")
A15: friccion | B15: =INDEX(enemigos!$B$3:$B$500,MATCH($A15,enemigos!$A$3:$A$500,0)) | C15: =INDEX(enemigos!$C$3:$C$500,MATCH($A15,enemigos!$A$3:$A$500,0)) | D15: =IF($C15="bicho",INDEX(enemigos!$D$3:$D$500,MATCH($A15,enemigos!$A$3:$A$500,0))*INDEX(ritmo!$B$3:$B$500,MATCH("dureza_vida",ritmo!$A$3:$A$500,0))*(1+$B$4/INDEX(ritmo!$B$3:$B$500,MATCH("vida_escala_seg",ritmo!$A$3:$A$500,0))),INDEX(enemigos!$D$3:$D$500,MATCH($A15,enemigos!$A$3:$A$500,0))) | E15: =IF(E$12>0,ROUNDUP($D15/E$12,0),"-") | F15: =IF(F$12>0,ROUNDUP($D15/F$12,0),"-") | G15: =IF(G$12>0,ROUNDUP($D15/G$12,0),"-") | H15: =IF(H$12>0,ROUNDUP($D15/H$12,0),"-") | I15: =IF(I$12>0,ROUNDUP($D15/I$12,0),"-") | J15: =IF(J$12>0,ROUNDUP($D15/J$12,0),"-") | K15: =IF(K$12>0,ROUNDUP($D15/K$12,0),"-") | L15: =IF(L$12>0,ROUNDUP($D15/L$12,0),"-") | ... BA15: =IF(BA$12>0,ROUNDUP($D15/BA$12,0),"-")
A16: robot | B16: =INDEX(enemigos!$B$3:$B$500,MATCH($A16,enemigos!$A$3:$A$500,0)) | C16: =INDEX(enemigos!$C$3:$C$500,MATCH($A16,enemigos!$A$3:$A$500,0)) | D16: =IF($C16="bicho",INDEX(enemigos!$D$3:$D$500,MATCH($A16,enemigos!$A$3:$A$500,0))*INDEX(ritmo!$B$3:$B$500,MATCH("dureza_vida",ritmo!$A$3:$A$500,0))*(1+$B$4/INDEX(ritmo!$B$3:$B$500,MATCH("vida_escala_seg",ritmo!$A$3:$A$500,0))),INDEX(enemigos!$D$3:$D$500,MATCH($A16,enemigos!$A$3:$A$500,0))) | E16: =IF(E$12>0,ROUNDUP($D16/E$12,0),"-") | F16: =IF(F$12>0,ROUNDUP($D16/F$12,0),"-") | G16: =IF(G$12>0,ROUNDUP($D16/G$12,0),"-") | H16: =IF(H$12>0,ROUNDUP($D16/H$12,0),"-") | I16: =IF(I$12>0,ROUNDUP($D16/I$12,0),"-") | J16: =IF(J$12>0,ROUNDUP($D16/J$12,0),"-") | K16: =IF(K$12>0,ROUNDUP($D16/K$12,0),"-") | L16: =IF(L$12>0,ROUNDUP($D16/L$12,0),"-") | ... BA16: =IF(BA$12>0,ROUNDUP($D16/BA$12,0),"-")
A17: polilla | B17: =INDEX(enemigos!$B$3:$B$500,MATCH($A17,enemigos!$A$3:$A$500,0)) | C17: =INDEX(enemigos!$C$3:$C$500,MATCH($A17,enemigos!$A$3:$A$500,0)) | D17: =IF($C17="bicho",INDEX(enemigos!$D$3:$D$500,MATCH($A17,enemigos!$A$3:$A$500,0))*INDEX(ritmo!$B$3:$B$500,MATCH("dureza_vida",ritmo!$A$3:$A$500,0))*(1+$B$4/INDEX(ritmo!$B$3:$B$500,MATCH("vida_escala_seg",ritmo!$A$3:$A$500,0))),INDEX(enemigos!$D$3:$D$500,MATCH($A17,enemigos!$A$3:$A$500,0))) | E17: =IF(E$12>0,ROUNDUP($D17/E$12,0),"-") | F17: =IF(F$12>0,ROUNDUP($D17/F$12,0),"-") | G17: =IF(G$12>0,ROUNDUP($D17/G$12,0),"-") | H17: =IF(H$12>0,ROUNDUP($D17/H$12,0),"-") | I17: =IF(I$12>0,ROUNDUP($D17/I$12,0),"-") | J17: =IF(J$12>0,ROUNDUP($D17/J$12,0),"-") | K17: =IF(K$12>0,ROUNDUP($D17/K$12,0),"-") | L17: =IF(L$12>0,ROUNDUP($D17/L$12,0),"-") | ... BA17: =IF(BA$12>0,ROUNDUP($D17/BA$12,0),"-")
A18: escarabajo | B18: =INDEX(enemigos!$B$3:$B$500,MATCH($A18,enemigos!$A$3:$A$500,0)) | C18: =INDEX(enemigos!$C$3:$C$500,MATCH($A18,enemigos!$A$3:$A$500,0)) | D18: =IF($C18="bicho",INDEX(enemigos!$D$3:$D$500,MATCH($A18,enemigos!$A$3:$A$500,0))*INDEX(ritmo!$B$3:$B$500,MATCH("dureza_vida",ritmo!$A$3:$A$500,0))*(1+$B$4/INDEX(ritmo!$B$3:$B$500,MATCH("vida_escala_seg",ritmo!$A$3:$A$500,0))),INDEX(enemigos!$D$3:$D$500,MATCH($A18,enemigos!$A$3:$A$500,0))) | E18: =IF(E$12>0,ROUNDUP($D18/E$12,0),"-") | F18: =IF(F$12>0,ROUNDUP($D18/F$12,0),"-") | G18: =IF(G$12>0,ROUNDUP($D18/G$12,0),"-") | H18: =IF(H$12>0,ROUNDUP($D18/H$12,0),"-") | I18: =IF(I$12>0,ROUNDUP($D18/I$12,0),"-") | J18: =IF(J$12>0,ROUNDUP($D18/J$12,0),"-") | K18: =IF(K$12>0,ROUNDUP($D18/K$12,0),"-") | L18: =IF(L$12>0,ROUNDUP($D18/L$12,0),"-") | ... BA18: =IF(BA$12>0,ROUNDUP($D18/BA$12,0),"-")
A19: rey | B19: =INDEX(enemigos!$B$3:$B$500,MATCH($A19,enemigos!$A$3:$A$500,0)) | C19: =INDEX(enemigos!$C$3:$C$500,MATCH($A19,enemigos!$A$3:$A$500,0)) | D19: =IF($C19="bicho",INDEX(enemigos!$D$3:$D$500,MATCH($A19,enemigos!$A$3:$A$500,0))*INDEX(ritmo!$B$3:$B$500,MATCH("dureza_vida",ritmo!$A$3:$A$500,0))*(1+$B$4/INDEX(ritmo!$B$3:$B$500,MATCH("vida_escala_seg",ritmo!$A$3:$A$500,0))),INDEX(enemigos!$D$3:$D$500,MATCH($A19,enemigos!$A$3:$A$500,0))) | E19: =IF(E$12>0,ROUNDUP($D19/E$12,0),"-") | F19: =IF(F$12>0,ROUNDUP($D19/F$12,0),"-") | G19: =IF(G$12>0,ROUNDUP($D19/G$12,0),"-") | H19: =IF(H$12>0,ROUNDUP($D19/H$12,0),"-") | I19: =IF(I$12>0,ROUNDUP($D19/I$12,0),"-") | J19: =IF(J$12>0,ROUNDUP($D19/J$12,0),"-") | K19: =IF(K$12>0,ROUNDUP($D19/K$12,0),"-") | L19: =IF(L$12>0,ROUNDUP($D19/L$12,0),"-") | ... BA19: =IF(BA$12>0,ROUNDUP($D19/BA$12,0),"-")
A20: cortadora | B20: =INDEX(enemigos!$B$3:$B$500,MATCH($A20,enemigos!$A$3:$A$500,0)) | C20: =INDEX(enemigos!$C$3:$C$500,MATCH($A20,enemigos!$A$3:$A$500,0)) | D20: =IF($C20="bicho",INDEX(enemigos!$D$3:$D$500,MATCH($A20,enemigos!$A$3:$A$500,0))*INDEX(ritmo!$B$3:$B$500,MATCH("dureza_vida",ritmo!$A$3:$A$500,0))*(1+$B$4/INDEX(ritmo!$B$3:$B$500,MATCH("vida_escala_seg",ritmo!$A$3:$A$500,0))),INDEX(enemigos!$D$3:$D$500,MATCH($A20,enemigos!$A$3:$A$500,0))) | E20: =IF(E$12>0,ROUNDUP($D20/E$12,0),"-") | F20: =IF(F$12>0,ROUNDUP($D20/F$12,0),"-") | G20: =IF(G$12>0,ROUNDUP($D20/G$12,0),"-") | H20: =IF(H$12>0,ROUNDUP($D20/H$12,0),"-") | I20: =IF(I$12>0,ROUNDUP($D20/I$12,0),"-") | J20: =IF(J$12>0,ROUNDUP($D20/J$12,0),"-") | K20: =IF(K$12>0,ROUNDUP($D20/K$12,0),"-") | L20: =IF(L$12>0,ROUNDUP($D20/L$12,0),"-") | ... BA20: =IF(BA$12>0,ROUNDUP($D20/BA$12,0),"-")
A21: tarantula | B21: =INDEX(enemigos!$B$3:$B$500,MATCH($A21,enemigos!$A$3:$A$500,0)) | C21: =INDEX(enemigos!$C$3:$C$500,MATCH($A21,enemigos!$A$3:$A$500,0)) | D21: =IF($C21="bicho",INDEX(enemigos!$D$3:$D$500,MATCH($A21,enemigos!$A$3:$A$500,0))*INDEX(ritmo!$B$3:$B$500,MATCH("dureza_vida",ritmo!$A$3:$A$500,0))*(1+$B$4/INDEX(ritmo!$B$3:$B$500,MATCH("vida_escala_seg",ritmo!$A$3:$A$500,0))),INDEX(enemigos!$D$3:$D$500,MATCH($A21,enemigos!$A$3:$A$500,0))) | E21: =IF(E$12>0,ROUNDUP($D21/E$12,0),"-") | F21: =IF(F$12>0,ROUNDUP($D21/F$12,0),"-") | G21: =IF(G$12>0,ROUNDUP($D21/G$12,0),"-") | H21: =IF(H$12>0,ROUNDUP($D21/H$12,0),"-") | I21: =IF(I$12>0,ROUNDUP($D21/I$12,0),"-") | J21: =IF(J$12>0,ROUNDUP($D21/J$12,0),"-") | K21: =IF(K$12>0,ROUNDUP($D21/K$12,0),"-") | L21: =IF(L$12>0,ROUNDUP($D21/L$12,0),"-") | ... BA21: =IF(BA$12>0,ROUNDUP($D21/BA$12,0),"-")
A22: gato | B22: =INDEX(enemigos!$B$3:$B$500,MATCH($A22,enemigos!$A$3:$A$500,0)) | C22: =INDEX(enemigos!$C$3:$C$500,MATCH($A22,enemigos!$A$3:$A$500,0)) | D22: =IF($C22="bicho",INDEX(enemigos!$D$3:$D$500,MATCH($A22,enemigos!$A$3:$A$500,0))*INDEX(ritmo!$B$3:$B$500,MATCH("dureza_vida",ritmo!$A$3:$A$500,0))*(1+$B$4/INDEX(ritmo!$B$3:$B$500,MATCH("vida_escala_seg",ritmo!$A$3:$A$500,0))),INDEX(enemigos!$D$3:$D$500,MATCH($A22,enemigos!$A$3:$A$500,0))) | E22: =IF(E$12>0,ROUNDUP($D22/E$12,0),"-") | F22: =IF(F$12>0,ROUNDUP($D22/F$12,0),"-") | G22: =IF(G$12>0,ROUNDUP($D22/G$12,0),"-") | H22: =IF(H$12>0,ROUNDUP($D22/H$12,0),"-") | I22: =IF(I$12>0,ROUNDUP($D22/I$12,0),"-") | J22: =IF(J$12>0,ROUNDUP($D22/J$12,0),"-") | K22: =IF(K$12>0,ROUNDUP($D22/K$12,0),"-") | L22: =IF(L$12>0,ROUNDUP($D22/L$12,0),"-") | ... BA22: =IF(BA$12>0,ROUNDUP($D22/BA$12,0),"-")
A23: proyector | B23: =INDEX(enemigos!$B$3:$B$500,MATCH($A23,enemigos!$A$3:$A$500,0)) | C23: =INDEX(enemigos!$C$3:$C$500,MATCH($A23,enemigos!$A$3:$A$500,0)) | D23: =IF($C23="bicho",INDEX(enemigos!$D$3:$D$500,MATCH($A23,enemigos!$A$3:$A$500,0))*INDEX(ritmo!$B$3:$B$500,MATCH("dureza_vida",ritmo!$A$3:$A$500,0))*(1+$B$4/INDEX(ritmo!$B$3:$B$500,MATCH("vida_escala_seg",ritmo!$A$3:$A$500,0))),INDEX(enemigos!$D$3:$D$500,MATCH($A23,enemigos!$A$3:$A$500,0))) | E23: =IF(E$12>0,ROUNDUP($D23/E$12,0),"-") | F23: =IF(F$12>0,ROUNDUP($D23/F$12,0),"-") | G23: =IF(G$12>0,ROUNDUP($D23/G$12,0),"-") | H23: =IF(H$12>0,ROUNDUP($D23/H$12,0),"-") | I23: =IF(I$12>0,ROUNDUP($D23/I$12,0),"-") | J23: =IF(J$12>0,ROUNDUP($D23/J$12,0),"-") | K23: =IF(K$12>0,ROUNDUP($D23/K$12,0),"-") | L23: =IF(L$12>0,ROUNDUP($D23/L$12,0),"-") | ... BA23: =IF(BA$12>0,ROUNDUP($D23/BA$12,0),"-")
A24: grua | B24: =INDEX(enemigos!$B$3:$B$500,MATCH($A24,enemigos!$A$3:$A$500,0)) | C24: =INDEX(enemigos!$C$3:$C$500,MATCH($A24,enemigos!$A$3:$A$500,0)) | D24: =IF($C24="bicho",INDEX(enemigos!$D$3:$D$500,MATCH($A24,enemigos!$A$3:$A$500,0))*INDEX(ritmo!$B$3:$B$500,MATCH("dureza_vida",ritmo!$A$3:$A$500,0))*(1+$B$4/INDEX(ritmo!$B$3:$B$500,MATCH("vida_escala_seg",ritmo!$A$3:$A$500,0))),INDEX(enemigos!$D$3:$D$500,MATCH($A24,enemigos!$A$3:$A$500,0))) | E24: =IF(E$12>0,ROUNDUP($D24/E$12,0),"-") | F24: =IF(F$12>0,ROUNDUP($D24/F$12,0),"-") | G24: =IF(G$12>0,ROUNDUP($D24/G$12,0),"-") | H24: =IF(H$12>0,ROUNDUP($D24/H$12,0),"-") | I24: =IF(I$12>0,ROUNDUP($D24/I$12,0),"-") | J24: =IF(J$12>0,ROUNDUP($D24/J$12,0),"-") | K24: =IF(K$12>0,ROUNDUP($D24/K$12,0),"-") | L24: =IF(L$12>0,ROUNDUP($D24/L$12,0),"-") | ... BA24: =IF(BA$12>0,ROUNDUP($D24/BA$12,0),"-")
... A46: gusano | B46: =INDEX(enemigos!$B$3:$B$500,MATCH($A46,enemigos!$A$3:$A$500,0)) | C46: =INDEX(enemigos!$C$3:$C$500,MATCH($A46,enemigos!$A$3:$A$500,0)) | D46: =IF($C46="bicho",INDEX(enemigos!$D$3:$D$500,MATCH($A46,enemigos!$A$3:$A$500,0))*INDEX(ritmo!$B$3:$B$500,MATCH("dureza_vida",ritmo!$A$3:$A$500,0))*(1+$B$4/INDEX(ritmo!$B$3:$B$500,MATCH("vida_escala_seg",ritmo!$A$3:$A$500,0))),INDEX(enemigos!$D$3:$D$500,MATCH($A46,enemigos!$A$3:$A$500,0))) | E46: =IF(E$12>0,ROUNDUP($D46/E$12,0),"-") | F46: =IF(F$12>0,ROUNDUP($D46/F$12,0),"-") | G46: =IF(G$12>0,ROUNDUP($D46/G$12,0),"-") | H46: =IF(H$12>0,ROUNDUP($D46/H$12,0),"-") | I46: =IF(I$12>0,ROUNDUP($D46/I$12,0),"-") | J46: =IF(J$12>0,ROUNDUP($D46/J$12,0),"-") | K46: =IF(K$12>0,ROUNDUP($D46/K$12,0),"-") | L46: =IF(L$12>0,ROUNDUP($D46/L$12,0),"-") | ... BA46: =IF(BA$12>0,ROUNDUP($D46/BA$12,0),"-")

Sheet Tiempo jefe
A1: Tiempo para matar a cada jefe
A2: Segundos estimados = vida ÷ (DPS supuesto × presencia). El DPS es un SUPUESTO por jefe (calibrar con __bossDuel: ver CLAUDE.md); no sale de la hoja armas.
A4: Presencia: fracción del tiempo en que el equipo logra pegarle al jefe (0 a 1) | B4: 0.8
A6: id | B6: nombre | C6: tipo | D6: vida (con segunda barra) | E6: DPS supuesto del equipo | F6: segundos para matarlo | G6: minutos
A7: rey | B7: =INDEX(enemigos!$B$3:$B$500,MATCH($A7,enemigos!$A$3:$A$500,0)) | C7: =INDEX(enemigos!$C$3:$C$500,MATCH($A7,enemigos!$A$3:$A$500,0)) | D7: =INDEX(enemigos!$D$3:$D$500,MATCH($A7,enemigos!$A$3:$A$500,0))*IF($C7="jefe_final",1+INDEX(ataques!$B$3:$B$500,MATCH("segunda_barra_vida",ataques!$A$3:$A$500,0)),1) | E7: 200 | F7: =IF($E7*$B$4>0,$D7/($E7*$B$4),"-") | G7: =IF(ISNUMBER($F7),$F7/60,"-")
A8: cortadora | B8: =INDEX(enemigos!$B$3:$B$500,MATCH($A8,enemigos!$A$3:$A$500,0)) | C8: =INDEX(enemigos!$C$3:$C$500,MATCH($A8,enemigos!$A$3:$A$500,0)) | D8: =INDEX(enemigos!$D$3:$D$500,MATCH($A8,enemigos!$A$3:$A$500,0))*IF($C8="jefe_final",1+INDEX(ataques!$B$3:$B$500,MATCH("segunda_barra_vida",ataques!$A$3:$A$500,0)),1) | E8: 200 | F8: =IF($E8*$B$4>0,$D8/($E8*$B$4),"-") | G8: =IF(ISNUMBER($F8),$F8/60,"-")
A9: tarantula | B9: =INDEX(enemigos!$B$3:$B$500,MATCH($A9,enemigos!$A$3:$A$500,0)) | C9: =INDEX(enemigos!$C$3:$C$500,MATCH($A9,enemigos!$A$3:$A$500,0)) | D9: =INDEX(enemigos!$D$3:$D$500,MATCH($A9,enemigos!$A$3:$A$500,0))*IF($C9="jefe_final",1+INDEX(ataques!$B$3:$B$500,MATCH("segunda_barra_vida",ataques!$A$3:$A$500,0)),1) | E9: 200 | F9: =IF($E9*$B$4>0,$D9/($E9*$B$4),"-") | G9: =IF(ISNUMBER($F9),$F9/60,"-")
A10: gato | B10: =INDEX(enemigos!$B$3:$B$500,MATCH($A10,enemigos!$A$3:$A$500,0)) | C10: =INDEX(enemigos!$C$3:$C$500,MATCH($A10,enemigos!$A$3:$A$500,0)) | D10: =INDEX(enemigos!$D$3:$D$500,MATCH($A10,enemigos!$A$3:$A$500,0))*IF($C10="jefe_final",1+INDEX(ataques!$B$3:$B$500,MATCH("segunda_barra_vida",ataques!$A$3:$A$500,0)),1) | E10: 200 | F10: =IF($E10*$B$4>0,$D10/($E10*$B$4),"-") | G10: =IF(ISNUMBER($F10),$F10/60,"-")
A11: proyector | B11: =INDEX(enemigos!$B$3:$B$500,MATCH($A11,enemigos!$A$3:$A$500,0)) | C11: =INDEX(enemigos!$C$3:$C$500,MATCH($A11,enemigos!$A$3:$A$500,0)) | D11: =INDEX(enemigos!$D$3:$D$500,MATCH($A11,enemigos!$A$3:$A$500,0))*IF($C11="jefe_final",1+INDEX(ataques!$B$3:$B$500,MATCH("segunda_barra_vida",ataques!$A$3:$A$500,0)),1) | E11: 200 | F11: =IF($E11*$B$4>0,$D11/($E11*$B$4),"-") | G11: =IF(ISNUMBER($F11),$F11/60,"-")
A12: grua | B12: =INDEX(enemigos!$B$3:$B$500,MATCH($A12,enemigos!$A$3:$A$500,0)) | C12: =INDEX(enemigos!$C$3:$C$500,MATCH($A12,enemigos!$A$3:$A$500,0)) | D12: =INDEX(enemigos!$D$3:$D$500,MATCH($A12,enemigos!$A$3:$A$500,0))*IF($C12="jefe_final",1+INDEX(ataques!$B$3:$B$500,MATCH("segunda_barra_vida",ataques!$A$3:$A$500,0)),1) | E12: 200 | F12: =IF($E12*$B$4>0,$D12/($E12*$B$4),"-") | G12: =IF(ISNUMBER($F12),$F12/60,"-")
A13: payaso | B13: =INDEX(enemigos!$B$3:$B$500,MATCH($A13,enemigos!$A$3:$A$500,0)) | C13: =INDEX(enemigos!$C$3:$C$500,MATCH($A13,enemigos!$A$3:$A$500,0)) | D13: =INDEX(enemigos!$D$3:$D$500,MATCH($A13,enemigos!$A$3:$A$500,0))*IF($C13="jefe_final",1+INDEX(ataques!$B$3:$B$500,MATCH("segunda_barra_vida",ataques!$A$3:$A$500,0)),1) | E13: 200 | F13: =IF($E13*$B$4>0,$D13/($E13*$B$4),"-") | G13: =IF(ISNUMBER($F13),$F13/60,"-")
A14: limpiafondos | B14: =INDEX(enemigos!$B$3:$B$500,MATCH($A14,enemigos!$A$3:$A$500,0)) | C14: =INDEX(enemigos!$C$3:$C$500,MATCH($A14,enemigos!$A$3:$A$500,0)) | D14: =INDEX(enemigos!$D$3:$D$500,MATCH($A14,enemigos!$A$3:$A$500,0))*IF($C14="jefe_final",1+INDEX(ataques!$B$3:$B$500,MATCH("segunda_barra_vida",ataques!$A$3:$A$500,0)),1) | E14: 200 | F14: =IF($E14*$B$4>0,$D14/($E14*$B$4),"-") | G14: =IF(ISNUMBER($F14),$F14/60,"-")
A15: muneco | B15: =INDEX(enemigos!$B$3:$B$500,MATCH($A15,enemigos!$A$3:$A$500,0)) | C15: =INDEX(enemigos!$C$3:$C$500,MATCH($A15,enemigos!$A$3:$A$500,0)) | D15: =INDEX(enemigos!$D$3:$D$500,MATCH($A15,enemigos!$A$3:$A$500,0))*IF($C15="jefe_final",1+INDEX(ataques!$B$3:$B$500,MATCH("segunda_barra_vida",ataques!$A$3:$A$500,0)),1) | E15: 200 | F15: =IF($E15*$B$4>0,$D15/($E15*$B$4),"-") | G15: =IF(ISNUMBER($F15),$F15/60,"-")
A16: perro | B16: =INDEX(enemigos!$B$3:$B$500,MATCH($A16,enemigos!$A$3:$A$500,0)) | C16: =INDEX(enemigos!$C$3:$C$500,MATCH($A16,enemigos!$A$3:$A$500,0)) | D16: =INDEX(enemigos!$D$3:$D$500,MATCH($A16,enemigos!$A$3:$A$500,0))*IF($C16="jefe_final",1+INDEX(ataques!$B$3:$B$500,MATCH("segunda_barra_vida",ataques!$A$3:$A$500,0)),1) | E16: 600 | F16: =IF($E16*$B$4>0,$D16/($E16*$B$4),"-") | G16: =IF(ISNUMBER($F16),$F16/60,"-")
A17: aspiradora | B17: =INDEX(enemigos!$B$3:$B$500,MATCH($A17,enemigos!$A$3:$A$500,0)) | C17: =INDEX(enemigos!$C$3:$C$500,MATCH($A17,enemigos!$A$3:$A$500,0)) | D17: =INDEX(enemigos!$D$3:$D$500,MATCH($A17,enemigos!$A$3:$A$500,0))*IF($C17="jefe_final",1+INDEX(ataques!$B$3:$B$500,MATCH("segunda_barra_vida",ataques!$A$3:$A$500,0)),1) | E17: 600 | F17: =IF($E17*$B$4>0,$D17/($E17*$B$4),"-") | G17: =IF(ISNUMBER($F17),$F17/60,"-")
A18: cortacercos | B18: =INDEX(enemigos!$B$3:$B$500,MATCH($A18,enemigos!$A$3:$A$500,0)) | C18: =INDEX(enemigos!$C$3:$C$500,MATCH($A18,enemigos!$A$3:$A$500,0)) | D18: =INDEX(enemigos!$D$3:$D$500,MATCH($A18,enemigos!$A$3:$A$500,0))*IF($C18="jefe_final",1+INDEX(ataques!$B$3:$B$500,MATCH("segunda_barra_vida",ataques!$A$3:$A$500,0)),1) | E18: 600 | F18: =IF($E18*$B$4>0,$D18/($E18*$B$4),"-") | G18: =IF(ISNUMBER($F18),$F18/60,"-")
... A20: gusano | B20: =INDEX(enemigos!$B$3:$B$500,MATCH($A20,enemigos!$A$3:$A$500,0)) | C20: =INDEX(enemigos!$C$3:$C$500,MATCH($A20,enemigos!$A$3:$A$500,0)) | D20: =INDEX(enemigos!$D$3:$D$500,MATCH($A20,enemigos!$A$3:$A$500,0))*IF($C20="jefe_final",1+INDEX(ataques!$B$3:$B$500,MATCH("segunda_barra_vida",ataques!$A$3:$A$500,0)),1) | E20: 600 | F20: =IF($E20*$B$4>0,$D20/($E20*$B$4),"-") | G20: =IF(ISNUMBER($F20),$F20/60,"-")

Sheet Partidas para comprar
A1: Partidas para comprar
A2: Precio ÷ tornillos promedio por partida, por cada nivel de mejora, auto, piloto, zona y pieza. Se recalcula con las hojas precios, autos, pilotos y ritmo.
A4: Tornillos promedio por partida (sale de ritmo tornillos_partida_tipica; el taller lo usa para decir cuántas partidas faltan) | B4: =INDEX(ritmo!$B$3:$B$500,MATCH("tornillos_partida_tipica",ritmo!$A$3:$A$500,0))
A5: Referencia: tiempo medio sobrevivido (s) | B5: 420
A6: Referencia: bajas medias por partida | B6: 600
A7: Referencia: jefes derrotados por partida | B7: 1
A8: Tornillos por partida según la fórmula del juego con esas referencias (no alimenta nada) | B8: =INT((B7*INDEX(ritmo!$B$3:$B$500,MATCH("tornillos_jefe",ritmo!$A$3:$A$500,0))+INT(B5/INDEX(ritmo!$B$3:$B$500,MATCH("tornillos_div_tiempo",ritmo!$A$3:$A$500,0)))+INT(B6*INDEX(ritmo!$B$3:$B$500,MATCH("dureza_xp",ritmo!$A$3:$A$500,0))/INDEX(ritmo!$B$3:$B$500,MATCH("tornillos_div_bajas",ritmo!$A$3:$A$500,0)))))
A10: tipo | B10: id | C10: nombre | D10: nivel1 | E10: nivel2 | F10: nivel3 | G10: nivel4 | H10: nivel5 | I10: nivel6 | J10: nivel7 | K10: nivel8 | L10: nivel9 | M10: nivel10 | N10: total
A11: mejora | B11: hp | C11: =INDEX(precios!$C$3:$C$500,MATCH($B11,precios!$A$3:$A$500,0)) | D11: =IF(INDEX(precios!$E$3:$E$500,MATCH($B11,precios!$A$3:$A$500,0))>0,INDEX(precios!$E$3:$E$500,MATCH($B11,precios!$A$3:$A$500,0))/$B$4,"") | E11: =IF(INDEX(precios!$F$3:$F$500,MATCH($B11,precios!$A$3:$A$500,0))>0,INDEX(precios!$F$3:$F$500,MATCH($B11,precios!$A$3:$A$500,0))/$B$4,"") | F11: =IF(INDEX(precios!$G$3:$G$500,MATCH($B11,precios!$A$3:$A$500,0))>0,INDEX(precios!$G$3:$G$500,MATCH($B11,precios!$A$3:$A$500,0))/$B$4,"") | G11: =IF(INDEX(precios!$H$3:$H$500,MATCH($B11,precios!$A$3:$A$500,0))>0,INDEX(precios!$H$3:$H$500,MATCH($B11,precios!$A$3:$A$500,0))/$B$4,"") | H11: =IF(INDEX(precios!$I$3:$I$500,MATCH($B11,precios!$A$3:$A$500,0))>0,INDEX(precios!$I$3:$I$500,MATCH($B11,precios!$A$3:$A$500,0))/$B$4,"") | I11: =IF(INDEX(precios!$J$3:$J$500,MATCH($B11,precios!$A$3:$A$500,0))>0,INDEX(precios!$J$3:$J$500,MATCH($B11,precios!$A$3:$A$500,0))/$B$4,"") | J11: =IF(INDEX(precios!$K$3:$K$500,MATCH($B11,precios!$A$3:$A$500,0))>0,INDEX(precios!$K$3:$K$500,MATCH($B11,precios!$A$3:$A$500,0))/$B$4,"") | K11: =IF(INDEX(precios!$L$3:$L$500,MATCH($B11,precios!$A$3:$A$500,0))>0,INDEX(precios!$L$3:$L$500,MATCH($B11,precios!$A$3:$A$500,0))/$B$4,"") | L11: =IF(INDEX(precios!$M$3:$M$500,MATCH($B11,precios!$A$3:$A$500,0))>0,INDEX(precios!$M$3:$M$500,MATCH($B11,precios!$A$3:$A$500,0))/$B$4,"") | M11: =IF(INDEX(precios!$N$3:$N$500,MATCH($B11,precios!$A$3:$A$500,0))>0,INDEX(precios!$N$3:$N$500,MATCH($B11,precios!$A$3:$A$500,0))/$B$4,"") | N11: =SUM(D11:M11)
A12: mejora | B12: dmg | C12: =INDEX(precios!$C$3:$C$500,MATCH($B12,precios!$A$3:$A$500,0)) | D12: =IF(INDEX(precios!$E$3:$E$500,MATCH($B12,precios!$A$3:$A$500,0))>0,INDEX(precios!$E$3:$E$500,MATCH($B12,precios!$A$3:$A$500,0))/$B$4,"") | E12: =IF(INDEX(precios!$F$3:$F$500,MATCH($B12,precios!$A$3:$A$500,0))>0,INDEX(precios!$F$3:$F$500,MATCH($B12,precios!$A$3:$A$500,0))/$B$4,"") | F12: =IF(INDEX(precios!$G$3:$G$500,MATCH($B12,precios!$A$3:$A$500,0))>0,INDEX(precios!$G$3:$G$500,MATCH($B12,precios!$A$3:$A$500,0))/$B$4,"") | G12: =IF(INDEX(precios!$H$3:$H$500,MATCH($B12,precios!$A$3:$A$500,0))>0,INDEX(precios!$H$3:$H$500,MATCH($B12,precios!$A$3:$A$500,0))/$B$4,"") | H12: =IF(INDEX(precios!$I$3:$I$500,MATCH($B12,precios!$A$3:$A$500,0))>0,INDEX(precios!$I$3:$I$500,MATCH($B12,precios!$A$3:$A$500,0))/$B$4,"") | I12: =IF(INDEX(precios!$J$3:$J$500,MATCH($B12,precios!$A$3:$A$500,0))>0,INDEX(precios!$J$3:$J$500,MATCH($B12,precios!$A$3:$A$500,0))/$B$4,"") | J12: =IF(INDEX(precios!$K$3:$K$500,MATCH($B12,precios!$A$3:$A$500,0))>0,INDEX(precios!$K$3:$K$500,MATCH($B12,precios!$A$3:$A$500,0))/$B$4,"") | K12: =IF(INDEX(precios!$L$3:$L$500,MATCH($B12,precios!$A$3:$A$500,0))>0,INDEX(precios!$L$3:$L$500,MATCH($B12,precios!$A$3:$A$500,0))/$B$4,"") | L12: =IF(INDEX(precios!$M$3:$M$500,MATCH($B12,precios!$A$3:$A$500,0))>0,INDEX(precios!$M$3:$M$500,MATCH($B12,precios!$A$3:$A$500,0))/$B$4,"") | M12: =IF(INDEX(precios!$N$3:$N$500,MATCH($B12,precios!$A$3:$A$500,0))>0,INDEX(precios!$N$3:$N$500,MATCH($B12,precios!$A$3:$A$500,0))/$B$4,"") | N12: =SUM(D12:M12)
A13: mejora | B13: spd | C13: =INDEX(precios!$C$3:$C$500,MATCH($B13,precios!$A$3:$A$500,0)) | D13: =IF(INDEX(precios!$E$3:$E$500,MATCH($B13,precios!$A$3:$A$500,0))>0,INDEX(precios!$E$3:$E$500,MATCH($B13,precios!$A$3:$A$500,0))/$B$4,"") | E13: =IF(INDEX(precios!$F$3:$F$500,MATCH($B13,precios!$A$3:$A$500,0))>0,INDEX(precios!$F$3:$F$500,MATCH($B13,precios!$A$3:$A$500,0))/$B$4,"") | F13: =IF(INDEX(precios!$G$3:$G$500,MATCH($B13,precios!$A$3:$A$500,0))>0,INDEX(precios!$G$3:$G$500,MATCH($B13,precios!$A$3:$A$500,0))/$B$4,"") | G13: =IF(INDEX(precios!$H$3:$H$500,MATCH($B13,precios!$A$3:$A$500,0))>0,INDEX(precios!$H$3:$H$500,MATCH($B13,precios!$A$3:$A$500,0))/$B$4,"") | H13: =IF(INDEX(precios!$I$3:$I$500,MATCH($B13,precios!$A$3:$A$500,0))>0,INDEX(precios!$I$3:$I$500,MATCH($B13,precios!$A$3:$A$500,0))/$B$4,"") | I13: =IF(INDEX(precios!$J$3:$J$500,MATCH($B13,precios!$A$3:$A$500,0))>0,INDEX(precios!$J$3:$J$500,MATCH($B13,precios!$A$3:$A$500,0))/$B$4,"") | J13: =IF(INDEX(precios!$K$3:$K$500,MATCH($B13,precios!$A$3:$A$500,0))>0,INDEX(precios!$K$3:$K$500,MATCH($B13,precios!$A$3:$A$500,0))/$B$4,"") | K13: =IF(INDEX(precios!$L$3:$L$500,MATCH($B13,precios!$A$3:$A$500,0))>0,INDEX(precios!$L$3:$L$500,MATCH($B13,precios!$A$3:$A$500,0))/$B$4,"") | L13: =IF(INDEX(precios!$M$3:$M$500,MATCH($B13,precios!$A$3:$A$500,0))>0,INDEX(precios!$M$3:$M$500,MATCH($B13,precios!$A$3:$A$500,0))/$B$4,"") | M13: =IF(INDEX(precios!$N$3:$N$500,MATCH($B13,precios!$A$3:$A$500,0))>0,INDEX(precios!$N$3:$N$500,MATCH($B13,precios!$A$3:$A$500,0))/$B$4,"") | N13: =SUM(D13:M13)
